<?xml version='1.0' encoding='utf-8'?>
<robot name="walker">
  <link name="left_leg">
    <visual name="left_leg_motor">
      <origin xyz="0 0.005 0" rpy="0 0 0" />
      <geometry>
        <box size="0.02 0.01 0.02" />
      </geometry>
      <material>
        <color rgba="1 0 0 0.5" />
      </material>
    </visual>
    <visual name="left_leg_axel">
      <origin xyz="0 0.008 0" rpy="0 0 0" />
      <geometry>
        <box size="0.005 0.016 0.005" />
      </geometry>
      <material>
        <color rgba="1 0 0 0.5" />
      </material>
    </visual>
    <visual name="left_leg_arm_axel">
      <origin xyz="0 -0.03125 0" rpy="0 0 0" />
      <geometry>
        <box size="0.005 0.0625 0.005" />
      </geometry>
      <material>
        <color rgba="1 0 0 0.5" />
      </material>
    </visual>
    <visual name="left_leg_arm">
      <origin xyz="0 -0.0625 -0.052" rpy="0 0 0" />
      <geometry>
        <box size="0.005 0.005 0.104" />
      </geometry>
      <material>
        <color rgba="1 0 0 0.5" />
      </material>
    </visual>
    <visual name="left_leg_hand_mass">
      <origin xyz="0 -0.0625 -0.104" rpy="0 0 0" />
      <geometry>
        <box size="0.02 0.02 0.02" />
      </geometry>
      <material>
        <color rgba="0 1 0 0.5" />
      </material>
    </visual>
    <visual name="left_leg_link">
      <origin xyz="0 0.016 -0.0765" rpy="0 0 0" />
      <geometry>
        <box size="0.005 0.005 0.153" />
      </geometry>
      <material>
        <color rgba="1 0 0 0.5" />
      </material>
    </visual>
    <visual name="left_leg_mass">
      <origin xyz="0 0.016 -0.0765" rpy="0 0 0" />
      <geometry>
        <box size="0.01 0.01 0.01" />
      </geometry>
      <material>
        <color rgba="0 1 0 0.5" />
      </material>
    </visual>
  </link>
  <link name="right_leg">
    <visual name="right_leg_motor">
      <origin xyz="0 -0.005 0" rpy="0 0 0" />
      <geometry>
        <box size="0.02 0.01 0.02" />
      </geometry>
      <material>
        <color rgba="0 0 1 0.5" />
      </material>
    </visual>
    <visual name="right_leg_axel">
      <origin xyz="0 -0.008 0" rpy="0 0 0" />
      <geometry>
        <box size="0.005 0.016 0.005" />
      </geometry>
      <material>
        <color rgba="0 0 1 0.5" />
      </material>
    </visual>
    <visual name="right_leg_arm_axel">
      <origin xyz="0 0.03125 0" rpy="0 0 0" />
      <geometry>
        <box size="0.005 0.0625 0.005" />
      </geometry>
      <material>
        <color rgba="0 0 1 0.5" />
      </material>
    </visual>
    <visual name="right_leg_arm">
      <origin xyz="0 0.0625 -0.052" rpy="0 0 0" />
      <geometry>
        <box size="0.005 0.005 0.104" />
      </geometry>
      <material>
        <color rgba="0 0 1 0.5" />
      </material>
    </visual>
    <visual name="right_leg_hand_mass">
      <origin xyz="0 0.0625 -0.104" rpy="0 0 0" />
      <geometry>
        <box size="0.02 0.02 0.02" />
      </geometry>
      <material>
        <color rgba="0 1 0 0.5" />
      </material>
    </visual>
    <visual name="right_leg_link">
      <origin xyz="0 -0.016 -0.0765" rpy="0 0 0" />
      <geometry>
        <box size="0.005 0.005 0.153" />
      </geometry>
      <material>
        <color rgba="0 0 1 0.5" />
      </material>
    </visual>
    <visual name="right_leg_mass">
      <origin xyz="0 -0.016 -0.0765" rpy="0 0 0" />
      <geometry>
        <box size="0.01 0.01 0.01" />
      </geometry>
      <material>
        <color rgba="0 1 0 0.5" />
      </material>
    </visual>
  </link>
  <link name="left_leg_hand_mass_link">
    <inertial name="left_leg_hand_mass_inertial">
      <origin xyz="0.0 -0.0625 -0.104" rpy="0 0 0" />
      <mass value="0.1" />
      <inertia ixx="0.0" ixy="0.0" ixz="0.0" iyy="0.0" iyz="0.0" izz="0.0" />
    </inertial>
  </link>
  <link name="left_leg_mass_link">
    <inertial name="left_leg_mass_inertial">
      <origin xyz="0.0 0.016 -0.0765" rpy="0 0 0" />
      <mass value="0.1" />
      <inertia ixx="0.0" ixy="0.0" ixz="0.0" iyy="0.0" iyz="0.0" izz="0.0" />
    </inertial>
  </link>
  <link name="left_foot">
    <inertial name="left_foot_inertial">
      <origin xyz="0.014 0.016 -0.153" rpy="0 0 0" />
      <mass value="0.1" />
      <inertia ixx="0.0" ixy="0.0" ixz="0.0" iyy="0.0" iyz="0.0" izz="0.0" />
    </inertial>
    <visual name="left_leg_foot_visual">
      <origin xyz="0.014 0.016 -0.153" rpy="0 0 0" />
      <geometry>
        <mesh filename="/home/sman/Desktop/Work/Research/LEGO-drake/mugatu/stickbot/X_0.24_Y_0.24_Z_0.24_box_x_0.101_box_y_0.0527/left_foot_geom.obj" />
      </geometry>
      <material>
        <color rgba="1 0 0 0.5" />
      </material>
    </visual>
    <collision name="left_leg_foot_collision">
      <origin xyz="0.014 0.016 -0.153" rpy="0 0 0" />
      <geometry>
        <mesh filename="/home/sman/Desktop/Work/Research/LEGO-drake/mugatu/stickbot/X_0.24_Y_0.24_Z_0.24_box_x_0.101_box_y_0.0527/left_foot_geom.obj" />
      </geometry>
      <material>
        <color rgba="1 0 0 0.5" />
      </material>
      <drake:proximity_properties>
        <drake:rigid_hydroelastic />
        <drake:mu_dynamic value="0.9" />
        <drake:mu_static value="0.9" />
        <drake:mesh_resolution_hint value="0.1" />
        <drake:hydroelastic_modulus value="50000000.0" />
      </drake:proximity_properties>
    </collision>
  </link>
  <link name="right_leg_hand_mass_link">
    <inertial name="right_leg_hand_mass_inertial">
      <origin xyz="0.0 0.0625 -0.104" rpy="0 0 0" />
      <mass value="0.1" />
      <inertia ixx="0.0" ixy="0.0" ixz="0.0" iyy="0.0" iyz="0.0" izz="0.0" />
    </inertial>
  </link>
  <link name="right_leg_mass_link">
    <inertial name="right_leg_mass_inertial">
      <origin xyz="0.0 -0.016 -0.0765" rpy="0 0 0" />
      <mass value="0.1" />
      <inertia ixx="0.0" ixy="0.0" ixz="0.0" iyy="0.0" iyz="0.0" izz="0.0" />
    </inertial>
  </link>
  <link name="right_foot">
    <inertial name="right_foot_inertial">
      <origin xyz="0.014 -0.016 -0.153" rpy="0 0 0" />
      <mass value="0.1" />
      <inertia ixx="0.0" ixy="0.0" ixz="0.0" iyy="0.0" iyz="0.0" izz="0.0" />
    </inertial>
    <visual name="right_leg_foot_visual">
      <origin xyz="0.014 -0.016 -0.153" rpy="0 0 0" />
      <geometry>
        <mesh filename="/home/sman/Desktop/Work/Research/LEGO-drake/mugatu/stickbot/X_0.24_Y_0.24_Z_0.24_box_x_0.101_box_y_0.0527/right_foot_geom.obj" />
      </geometry>
      <material>
        <color rgba="0 0 1 0.5" />
      </material>
    </visual>
    <collision name="right_leg_foot_collision">
      <origin xyz="0.014 -0.016 -0.153" rpy="0 0 0" />
      <geometry>
        <mesh filename="/home/sman/Desktop/Work/Research/LEGO-drake/mugatu/stickbot/X_0.24_Y_0.24_Z_0.24_box_x_0.101_box_y_0.0527/right_foot_geom.obj" />
      </geometry>
      <material>
        <color rgba="0 0 1 0.5" />
      </material>
      <drake:proximity_properties>
        <drake:rigid_hydroelastic />
        <drake:mu_dynamic value="0.9" />
        <drake:mu_static value="0.9" />
        <drake:mesh_resolution_hint value="0.1" />
        <drake:hydroelastic_modulus value="50000000.0" />
      </drake:proximity_properties>
    </collision>
  </link>
  <joint name="hip" type="revolute">
    <origin xyz="0 0 0" rpy="0 0 0" />
    <parent link="left_leg" />
    <child link="right_leg" />
    <axis xyz="0 1 0" />
    <limit lower="-0.785" upper="0.785" />
  </joint>
  <joint name="fixed_left_leg_hand_mass_link" type="fixed">
    <origin xyz="0 0 0" rpy="0 0 0" />
    <parent link="left_leg" />
    <child link="left_leg_hand_mass_link" />
  </joint>
  <joint name="fixed_left_leg_mass_link" type="fixed">
    <origin xyz="0 0 0" rpy="0 0 0" />
    <parent link="left_leg" />
    <child link="left_leg_mass_link" />
  </joint>
  <joint name="fixed_left_foot" type="fixed">
    <origin xyz="0 0 0" rpy="0 0 0" />
    <parent link="left_leg" />
    <child link="left_foot" />
  </joint>
  <joint name="fixed_right_leg_hand_mass_link" type="fixed">
    <origin xyz="0 0 0" rpy="0 0 0" />
    <parent link="right_leg" />
    <child link="right_leg_hand_mass_link" />
  </joint>
  <joint name="fixed_right_leg_mass_link" type="fixed">
    <origin xyz="0 0 0" rpy="0 0 0" />
    <parent link="right_leg" />
    <child link="right_leg_mass_link" />
  </joint>
  <joint name="fixed_right_foot" type="fixed">
    <origin xyz="0 0 0" rpy="0 0 0" />
    <parent link="right_leg" />
    <child link="right_foot" />
  </joint>
  <transmission name="hip_joint_transmission">
    <type>transmission_interface/SimpleTransmission</type>
    <joint name="hip">
      <hardwareInterface>hardware_interface/EffortJointInterface</hardwareInterface>
    </joint>
    <actuator name="hip_joint_motor">
      <hardwareInterface>hardware_interface/EffortJointInterface</hardwareInterface>
    </actuator>
    <mechanicalReduction>1.0</mechanicalReduction>
  </transmission>
  <link name="ground">
    <visual>
      <origin xyz="0 0 -0.25" rpy="0 0 0" />
      <geometry>
        <box size="10 10 0.5" />
      </geometry>
      <material>
        <color rgba="0.93 .74 .4 1" />
      </material>
    </visual>
    <collision>
      <origin xyz="0 0 -0.25" rpy="0 0 0" />
      <geometry>
        <box size="10 10 0.5" />
      </geometry>
      <drake:rigid_hydroelastic />
      <drake:mu_dynamic value="0.9" />
      <drake:mu_static value="0.9" />
      <drake:mesh_resolution_hint value="0.1" />
      <drake:hydroelastic_modulus value="50000000.0" />
    </collision>
  </link>
  <joint name="fixed_ground" type="fixed">
    <origin xyz="0 0 0" rpy="0 0 0" />
    <parent link="world" />
    <child link="ground" />
  </joint>
  <mujoco>
    <compiler strippath="false" />
  </mujoco>
</robot>